<?xml version="1.0" ?>
<!-- =================================================================================== -->
<!-- |    This document was autogenerated by xacro from /home/aviral/anveshika_ws/src/Anveshika/anveshika_description/urdf/anveshika.urdf.xacro | -->
<!-- |    EDITING THIS FILE BY HAND IS NOT RECOMMENDED                                 | -->
<!-- =================================================================================== -->
<robot name="anveshika">
  <link name="base_footprint"/>
  <joint name="base_joint" type="fixed">
    <parent link="base_footprint"/>
    <child link="base_link"/>
    <origin rpy="0 0 0" xyz="0 0 0.235"/>
  </joint>
  <link name="base_link">
    <visual>
      <geometry>
        <mesh filename="package://anveshika_description/meshes/rover/box.stl" scale="0.001 0.001 0.001"/>
      </geometry>
      <origin rpy="0 0 0" xyz="0 0 0"/>
    </visual>
    <collision>
      <geometry>
        <box size="0.36 0.30 0.12"/>
      </geometry>
      <origin rpy="0 0 0" xyz="0 0 0.045"/>
    </collision>
    <inertial>
      <origin rpy="0 0 0" xyz="0 0 0"/>
      <mass value="4.0"/>
      <inertia ixx="0.05835" ixy="0" ixz="-0.0008805" iyy="0.06894" iyz="0" izz="0.09218"/>
    </inertial>
  </link>
  <gazebo reference="base_link">
    <material>Gazebo/Red</material>
    <!-- <sensor name="imu_sensor" type="imu">
            <always_on>1</always_on>
            <update_rate>1</update_rate>
            <visualize>true</visualize>
            <topic>imu</topic>
        </sensor> -->
  </gazebo>
  <joint name="realsense_joint" type="fixed">
    <parent link="base_link"/>
    <child link="realsense_d435i_bottom_screw_frame"/>
    <origin rpy="0 0 0" xyz="0.17 0 0.11"/>
  </joint>
  <material name="realsense_d435i_aluminum">
    <color rgba="0.5 0.5 0.5 1"/>
  </material>
  <link name="realsense_d435i_bottom_screw_frame"/>
  <joint name="realsense_d435i_link_joint" type="fixed">
    <origin rpy="0 0 0" xyz="0 0.0175 0.0125"/>
    <parent link="realsense_d435i_bottom_screw_frame"/>
    <child link="realsense_d435i_link"/>
  </joint>
  <link name="realsense_d435i_link">
    <visual>
      <origin rpy="1.5707963267948966 0 1.5707963267948966" xyz="0.0149 -0.0175 0"/>
      <geometry>
        <mesh filename="package://anveshika_description/meshes/d435.dae"/>
      </geometry>
      <material name="realsense_d435i_aluminum"/>
    </visual>
    <collision>
      <origin rpy="0 0 0" xyz="0 -0.0175 0"/>
      <geometry>
        <box size="0.02505 0.09 0.025"/>
      </geometry>
    </collision>
    <inertial>
      <!-- The following are not reliable values, and should not be used for modeling -->
      <mass value="0.564"/>
      <origin xyz="0 0 0"/>
      <inertia ixx="0.003881243" ixy="0.0" ixz="0.0" iyy="0.000498940" iyz="0.0" izz="0.003879257"/>
    </inertial>
  </link>
  <!-- camera depth joints and links -->
  <joint name="realsense_d435i_depth_joint" type="fixed">
    <origin rpy="0 0 0" xyz="0 0 0"/>
    <parent link="realsense_d435i_link"/>
    <child link="realsense_d435i_depth_frame"/>
  </joint>
  <link name="realsense_d435i_depth_frame"/>
  <joint name="realsense_d435i_depth_optical_joint" type="fixed">
    <origin rpy="-1.5707963267948966 0 -1.5707963267948966" xyz="0 0 0"/>
    <parent link="realsense_d435i_depth_frame"/>
    <child link="realsense_d435i_depth_optical_frame"/>
  </joint>
  <link name="realsense_d435i_depth_optical_frame"/>
  <!-- camera left IR joints and links -->
  <joint name="realsense_d435i_left_ir_joint" type="fixed">
    <origin rpy="0 0 0" xyz="0 0.0 0"/>
    <parent link="realsense_d435i_depth_frame"/>
    <child link="realsense_d435i_left_ir_frame"/>
  </joint>
  <link name="realsense_d435i_left_ir_frame"/>
  <joint name="realsense_d435i_left_ir_optical_joint" type="fixed">
    <origin rpy="-1.5707963267948966 0 -1.5707963267948966" xyz="0 0 0"/>
    <parent link="realsense_d435i_left_ir_frame"/>
    <child link="realsense_d435i_left_ir_optical_frame"/>
  </joint>
  <link name="realsense_d435i_left_ir_optical_frame"/>
  <!-- camera right IR joints and links -->
  <joint name="realsense_d435i_right_ir_joint" type="fixed">
    <origin rpy="0 0 0" xyz="0 -0.05 0"/>
    <parent link="realsense_d435i_depth_frame"/>
    <child link="realsense_d435i_right_ir_frame"/>
  </joint>
  <link name="realsense_d435i_right_ir_frame"/>
  <joint name="realsense_d435i_right_ir_optical_joint" type="fixed">
    <origin rpy="-1.5707963267948966 0 -1.5707963267948966" xyz="0 0 0"/>
    <parent link="realsense_d435i_right_ir_frame"/>
    <child link="realsense_d435i_right_ir_optical_frame"/>
  </joint>
  <link name="realsense_d435i_right_ir_optical_frame"/>
  <!-- camera color joints and links -->
  <joint name="realsense_d435i_color_joint" type="fixed">
    <origin rpy="0 0 0" xyz="0 0.015 0"/>
    <parent link="realsense_d435i_depth_frame"/>
    <child link="realsense_d435i_color_frame"/>
  </joint>
  <link name="realsense_d435i_color_frame"/>
  <joint name="realsense_d435i_color_optical_joint" type="fixed">
    <origin rpy="-1.5707963267948966 0 -1.5707963267948966" xyz="0 0 0"/>
    <parent link="realsense_d435i_color_frame"/>
    <child link="realsense_d435i_color_optical_frame"/>
  </joint>
  <link name="realsense_d435i_color_optical_frame"/>
  <!-- camera accel joints and links -->
  <joint name="realsense_d435i_accel_joint" type="fixed">
    <origin rpy="0 0 0" xyz="-0.00174 0.00552 0.0176"/>
    <parent link="realsense_d435i_link"/>
    <child link="realsense_d435i_accel_frame"/>
  </joint>
  <link name="realsense_d435i_accel_frame"/>
  <joint name="realsense_d435i_accel_optical_joint" type="fixed">
    <origin rpy="-1.5707963267948966 0 -1.5707963267948966" xyz="0 0 0"/>
    <parent link="realsense_d435i_accel_frame"/>
    <child link="realsense_d435i_accel_optical_frame"/>
  </joint>
  <link name="realsense_d435i_accel_optical_frame"/>
  <!-- camera gyro joints and links -->
  <joint name="realsense_d435i_gyro_joint" type="fixed">
    <origin rpy="0 0 0" xyz="-0.00174 0.00552 0.0176"/>
    <parent link="realsense_d435i_link"/>
    <child link="realsense_d435i_gyro_frame"/>
  </joint>
  <link name="realsense_d435i_gyro_frame"/>
  <joint name="realsense_d435i_gyro_optical_joint" type="fixed">
    <origin rpy="-1.5707963267948966 0 -1.5707963267948966" xyz="0 0 0"/>
    <parent link="realsense_d435i_gyro_frame"/>
    <child link="realsense_d435i_gyro_optical_frame"/>
  </joint>
  <link name="realsense_d435i_gyro_optical_frame"/>
  <gazebo reference="realsense_d435i_link">
    <self_collide>0</self_collide>
    <enable_wind>0</enable_wind>
    <kinematic>0</kinematic>
    <!-- <gravity>1</gravity> -->
    <!--<mu>1</mu>-->
    <mu2>1</mu2>
    <fdir1>0 0 0</fdir1>
    <!--<slip1>0</slip1>
      <slip2>0</slip2>-->
    <kp>1e+13</kp>
    <kd>1</kd>
    <!--<max_vel>0.01</max_vel>
      <min_depth>0</min_depth>-->
    <sensor name="realsense_d435i_color" type="camera">
      <camera name="realsense_d435i">
        <horizontal_fov>1.2112585008840648</horizontal_fov>
        <image>
          <width>1920</width>
          <height>1080</height>
          <format>RGB_INT8</format>
        </image>
        <clip>
          <near>0.1</near>
          <far>100</far>
        </clip>
        <noise>
          <type>gaussian</type>
          <mean>0.0</mean>
          <stddev>0.007</stddev>
        </noise>
        <optical_frame_id>realsense_d435i_color_optical_frame</optical_frame_id>
        <camera_info_topic>realsense_d435i/color/camera_info</camera_info_topic>
      </camera>
      <always_on>1</always_on>
      <update_rate>30</update_rate>
      <visualize>False</visualize>
      <topic>realsense_d435i/color/image</topic>
    </sensor>
    <sensor name="realsense_d435i_ired1" type="camera">
      <camera name="realsense_d435i">
        <horizontal_fov>1.4870205226991688</horizontal_fov>
        <image>
          <width>640</width>
          <height>480</height>
          <format>L_INT8</format>
        </image>
        <clip>
          <near>0.1</near>
          <far>100</far>
        </clip>
        <noise>
          <type>gaussian</type>
          <mean>0.0</mean>
          <stddev>0.05</stddev>
        </noise>
        <optical_frame_id>realsense_d435i_left_ir_optical_frame</optical_frame_id>
        <camera_info_topic>realsense_d435i/infra_1/camera_info</camera_info_topic>
      </camera>
      <always_on>1</always_on>
      <update_rate>30</update_rate>
      <visualize>false</visualize>
      <topic>realsense_d435i/infra_1/image</topic>
    </sensor>
    <sensor name="realsense_d435i_ired2" type="camera">
      <camera name="realsense_d435i">
        <horizontal_fov>1.4870205226991688</horizontal_fov>
        <image>
          <width>640</width>
          <height>480</height>
          <format>L_INT8</format>
        </image>
        <clip>
          <near>0.1</near>
          <far>100</far>
        </clip>
        <noise>
          <type>gaussian</type>
          <mean>0.0</mean>
          <stddev>0.05</stddev>
        </noise>
        <optical_frame_id>realsense_d435i_right_ir_optical_frame</optical_frame_id>
        <camera_info_topic>realsense_d435i/infra_2/camera_info</camera_info_topic>
      </camera>
      <always_on>1</always_on>
      <update_rate>30</update_rate>
      <visualize>false</visualize>
      <topic>realsense_d435i/infra_2/image</topic>
    </sensor>
    <sensor name="realsense_d435i_depth" type="depth">
      <camera name="realsense_d435i">
        <horizontal_fov>1.2112585008840648</horizontal_fov>
        <image>
          <width>1920</width>
          <height>1080</height>
        </image>
        <clip>
          <near>0.1</near>
          <far>6.0</far>
        </clip>
        <noise>
          <type>gaussian</type>
          <mean>0.0</mean>
          <stddev>0.100</stddev>
        </noise>
        <optical_frame_id>realsense_d435i_depth_optical_frame</optical_frame_id>
        <camera_info_topic>realsense_d435i/depth/camera_info</camera_info_topic>
      </camera>
      <always_on>1</always_on>
      <update_rate>30</update_rate>
      <visualize>false</visualize>
      <topic>realsense_d435i/depth/depth_image</topic>
    </sensor>
    <sensor name="realsense_d435i_imu" type="imu">
      <always_on>true</always_on>
      <update_rate>400</update_rate>
      <topic>realsense_d435i/imu</topic>
    </sensor>
  </gazebo>
  <link name="left_bogie">
    <visual>
      <geometry>
        <mesh filename="package://anveshika_description/meshes/rover/left_bogie.stl" scale="0.001 0.001 0.001"/>
      </geometry>
      <origin rpy="0 0 3.141592653589793" xyz="0 0 0"/>
    </visual>
    <collision>
      <geometry>
        <mesh filename="package://anveshika_description/meshes/rover/collision_bogie.stl" scale="0.001 0.001 0.001"/>
      </geometry>
      <origin rpy="0 0 0" xyz="0 -0.015 0"/>
    </collision>
    <inertial>
      <origin rpy="0 0 3.141592653589793" xyz="0 0 0"/>
      <mass value="1.0"/>
      <inertia ixx="0.008645" ixy="0" ixz="0.0001546" iyy="0.05017" iyz="0.001152" izz="0.04221"/>
    </inertial>
  </link>
  <gazebo reference="left_bogie">
    <material>Gazebo/Red</material>
  </gazebo>
  <joint name="base_left_bogie_joint" type="revolute">
    <parent link="base_link"/>
    <child link="left_bogie"/>
    <origin rpy="0 0 0" xyz="0 0.190 0.06"/>
    <axis xyz="0 1 0"/>
    <limit effort="0" lower="-1.5707963267948966" upper="1.5707963267948966" velocity="100"/>
  </joint>
  <link name="right_bogie">
    <visual>
      <geometry>
        <mesh filename="package://anveshika_description/meshes/rover/right_bogie.stl" scale="0.001 0.001 0.001"/>
      </geometry>
      <origin rpy="0 0 3.141592653589793" xyz="0 0 0"/>
    </visual>
    <collision>
      <geometry>
        <mesh filename="package://anveshika_description/meshes/rover/collision_bogie.stl" scale="0.001 0.001 0.001"/>
      </geometry>
      <origin rpy="0 0 0" xyz="0 0.015 0"/>
    </collision>
    <inertial>
      <origin rpy="0 0 3.141592653589793" xyz="0 0 0"/>
      <mass value="1.0"/>
      <inertia ixx="0.008645" ixy="0" ixz="0.0001546" iyy="0.05017" iyz="-0.001152" izz="0.04221"/>
    </inertial>
  </link>
  <gazebo reference="right_bogie">
    <material>Gazebo/Red</material>
  </gazebo>
  <joint name="base_right_bogie_joint" type="revolute">
    <parent link="base_link"/>
    <child link="right_bogie"/>
    <origin rpy="0 0 0" xyz="0 -0.190 0.06"/>
    <axis xyz="0 -1.0 0"/>
    <limit effort="0" lower="-1.5707963267948966" upper="1.5707963267948966" velocity="100"/>
    <mimic joint="base_left_bogie_joint" multiplier="1"/>
  </joint>
  <link name="front_left_motor_mount">
    <visual>
      <geometry>
        <mesh filename="package://anveshika_description/meshes/rover/drive_motor_mount.stl" scale="0.001 0.001 0.001"/>
      </geometry>
      <origin rpy="0 0 -1.5707963267948966" xyz="0 0 0"/>
    </visual>
    <collision>
      <geometry>
        <mesh filename="package://anveshika_description/meshes/rover/collision_motor_mount.stl" scale="0.001 0.001 0.001"/>
      </geometry>
      <origin rpy="0 0 -1.5707963267948966" xyz="0 0 0"/>
    </collision>
    <inertial>
      <origin rpy="0 0 -1.5707963267948966" xyz="0 0 0"/>
      <mass value="0.3"/>
      <inertia ixx="0.0003244" ixy="0" ixz="-0.0002914" iyy="0.001012" iyz="0" izz="0.0007519"/>
    </inertial>
  </link>
  <gazebo reference="front_left_motor_mount">
    <material>Gazebo/Red</material>
  </gazebo>
  <joint name="left_bogie_front_left_motor_mount_joint" type="revolute">
    <parent link="left_bogie"/>
    <child link="front_left_motor_mount"/>
    <origin rpy="0 0 0" xyz="0.25 -0.005 -0.223"/>
    <axis xyz="0 0 1"/>
    <limit effort="100" lower="-1.5707963267948966" upper="1.5707963267948966" velocity="100"/>
    <command_interface name="position">
      <param name="min">-1.5707963267948966</param>
      <param name="max">1.5707963267948966</param>
    </command_interface>
    <state_interface name="position"/>
    <state_interface name="velocity"/>
    <state_interface name="acceleration"/>
  </joint>
  <link name="back_left_motor_mount">
    <visual>
      <geometry>
        <mesh filename="package://anveshika_description/meshes/rover/drive_motor_mount.stl" scale="0.001 0.001 0.001"/>
      </geometry>
      <origin rpy="0 0 -1.5707963267948966" xyz="0 0 0"/>
    </visual>
    <collision>
      <geometry>
        <mesh filename="package://anveshika_description/meshes/rover/collision_motor_mount.stl" scale="0.001 0.001 0.001"/>
      </geometry>
      <origin rpy="0 0 -1.5707963267948966" xyz="0 0 0"/>
    </collision>
    <inertial>
      <origin rpy="0 0 -1.5707963267948966" xyz="0 0 0"/>
      <mass value="0.3"/>
      <inertia ixx="0.0003244" ixy="0" ixz="-0.0002914" iyy="0.001012" iyz="0" izz="0.0007519"/>
    </inertial>
  </link>
  <gazebo reference="back_left_motor_mount">
    <material>Gazebo/Red</material>
  </gazebo>
  <joint name="left_bogie_back_left_motor_mount_joint" type="revolute">
    <parent link="left_bogie"/>
    <child link="back_left_motor_mount"/>
    <origin rpy="0 0 0" xyz="-0.25 -0.005 -0.223"/>
    <axis xyz="0 0 1"/>
    <limit effort="100" lower="-1.5707963267948966" upper="1.5707963267948966" velocity="100"/>
    <command_interface name="position">
      <param name="min">-1.5707963267948966</param>
      <param name="max">1.5707963267948966</param>
    </command_interface>
    <state_interface name="position"/>
    <state_interface name="velocity"/>
    <state_interface name="acceleration"/>
  </joint>
  <link name="front_right_motor_mount">
    <visual>
      <geometry>
        <mesh filename="package://anveshika_description/meshes/rover/drive_motor_mount.stl" scale="0.001 0.001 0.001"/>
      </geometry>
      <origin rpy="0 0 1.5707963267948966" xyz="0 0 0"/>
    </visual>
    <collision>
      <geometry>
        <mesh filename="package://anveshika_description/meshes/rover/collision_motor_mount.stl" scale="0.001 0.001 0.001"/>
      </geometry>
      <origin rpy="0 0 1.5707963267948966" xyz="0 0 0"/>
    </collision>
    <inertial>
      <origin rpy="0 0 1.5707963267948966" xyz="0 0 0"/>
      <mass value="0.3"/>
      <inertia ixx="0.0003244" ixy="0" ixz="-0.0002914" iyy="0.001012" iyz="0" izz="0.0007519"/>
    </inertial>
  </link>
  <gazebo reference="front_right_motor_mount">
    <material>Gazebo/Red</material>
  </gazebo>
  <joint name="right_bogie_front_right_motor_mount_joint" type="revolute">
    <parent link="right_bogie"/>
    <child link="front_right_motor_mount"/>
    <origin rpy="0 0 0" xyz="0.25 0.005 -0.223"/>
    <axis xyz="0 0 1"/>
    <limit effort="100" lower="-1.5707963267948966" upper="1.5707963267948966" velocity="100"/>
    <command_interface name="position">
      <param name="min">-1.5707963267948966</param>
      <param name="max">1.5707963267948966</param>
    </command_interface>
    <state_interface name="position"/>
    <state_interface name="velocity"/>
    <state_interface name="acceleration"/>
  </joint>
  <link name="back_right_motor_mount">
    <visual>
      <geometry>
        <mesh filename="package://anveshika_description/meshes/rover/drive_motor_mount.stl" scale="0.001 0.001 0.001"/>
      </geometry>
      <origin rpy="0 0 1.5707963267948966" xyz="0 0 0"/>
    </visual>
    <collision>
      <geometry>
        <mesh filename="package://anveshika_description/meshes/rover/collision_motor_mount.stl" scale="0.001 0.001 0.001"/>
      </geometry>
      <origin rpy="0 0 1.5707963267948966" xyz="0 0 0"/>
    </collision>
    <inertial>
      <origin rpy="0 0 1.5707963267948966" xyz="0 0 0"/>
      <mass value="0.3"/>
      <inertia ixx="0.0003244" ixy="0" ixz="-0.0002914" iyy="0.001012" iyz="0" izz="0.0007519"/>
    </inertial>
  </link>
  <gazebo reference="back_right_motor_mount">
    <material>Gazebo/Red</material>
  </gazebo>
  <joint name="right_bogie_back_right_motor_mount_joint" type="revolute">
    <parent link="right_bogie"/>
    <child link="back_right_motor_mount"/>
    <origin rpy="0 0 0" xyz="-0.25 0.005 -0.223"/>
    <axis xyz="0 0 1"/>
    <limit effort="100" lower="-1.5707963267948966" upper="1.5707963267948966" velocity="100"/>
    <command_interface name="position">
      <param name="min">-1.5707963267948966</param>
      <param name="max">1.5707963267948966</param>
    </command_interface>
    <state_interface name="position"/>
    <state_interface name="velocity"/>
    <state_interface name="acceleration"/>
  </joint>
  <link name="front_left_wheel">
    <visual>
      <geometry>
        <mesh filename="package://anveshika_description/meshes/rover/wheel.stl" scale="0.001 0.001 0.001"/>
      </geometry>
      <origin rpy="1.5707963267948966 0 0" xyz="0 0 0"/>
    </visual>
    <collision>
      <geometry>
        <cylinder length="0.1" radius="0.06"/>
      </geometry>
      <origin rpy="1.5707963267948966 0 0" xyz="0 -0.05 0"/>
    </collision>
    <inertial>
      <origin rpy="1.5707963267948966 0 0" xyz="0 0 0"/>
      <mass value="0.45"/>
      <inertia ixx="0.001735" ixy="0" ixz="0" iyy="0.001735" iyz="0" izz="0.0008776"/>
    </inertial>
  </link>
  <gazebo reference="front_left_wheel">
    <material>Gazebo/Red</material>
  </gazebo>
  <joint name="front_left_wheel_joint" type="continuous">
    <parent link="front_left_motor_mount"/>
    <child link="front_left_wheel"/>
    <origin rpy="0 0 0" xyz="0 0.045 -0.006"/>
    <axis xyz="0 1 0"/>
    <command_interface name="velocity">
      <param name="min">-1</param>
      <param name="max">1</param>
    </command_interface>
    <state_interface name="position"/>
    <state_interface name="velocity"/>
    <state_interface name="acceleration"/>
  </joint>
  <link name="back_left_wheel">
    <visual>
      <geometry>
        <mesh filename="package://anveshika_description/meshes/rover/wheel.stl" scale="0.001 0.001 0.001"/>
      </geometry>
      <origin rpy="1.5707963267948966 0 0" xyz="0 0 0"/>
    </visual>
    <collision>
      <geometry>
        <cylinder length="0.1" radius="0.06"/>
      </geometry>
      <origin rpy="1.5707963267948966 0 0" xyz="0 -0.05 0"/>
    </collision>
    <inertial>
      <origin rpy="1.5707963267948966 0 0" xyz="0 0 0"/>
      <mass value="0.45"/>
      <inertia ixx="0.001735" ixy="0" ixz="0" iyy="0.001735" iyz="0" izz="0.0008776"/>
    </inertial>
  </link>
  <gazebo reference="back_left_wheel">
    <material>Gazebo/Red</material>
  </gazebo>
  <joint name="back_left_wheel_joint" type="continuous">
    <parent link="back_left_motor_mount"/>
    <child link="back_left_wheel"/>
    <origin rpy="0 0 0" xyz="0 0.045 -0.006"/>
    <axis xyz="0 1 0"/>
    <command_interface name="velocity">
      <param name="min">-1</param>
      <param name="max">1</param>
    </command_interface>
    <state_interface name="position"/>
    <state_interface name="velocity"/>
    <state_interface name="acceleration"/>
  </joint>
  <link name="front_right_wheel">
    <visual>
      <geometry>
        <mesh filename="package://anveshika_description/meshes/rover/wheel.stl" scale="0.001 0.001 0.001"/>
      </geometry>
      <origin rpy="-1.5707963267948966 0 0" xyz="0 0 0"/>
    </visual>
    <collision>
      <geometry>
        <cylinder length="0.1" radius="0.06"/>
      </geometry>
      <origin rpy="-1.5707963267948966 0 0" xyz="0 0.05 0"/>
    </collision>
    <inertial>
      <origin rpy="-1.5707963267948966 0 0" xyz="0 0 0"/>
      <mass value="0.45"/>
      <inertia ixx="0.001735" ixy="0" ixz="0" iyy="0.001735" iyz="0" izz="0.0008776"/>
    </inertial>
  </link>
  <gazebo reference="front_right_wheel">
    <material>Gazebo/Red</material>
  </gazebo>
  <joint name="front_right_wheel_joint" type="continuous">
    <parent link="front_right_motor_mount"/>
    <child link="front_right_wheel"/>
    <origin rpy="0 0 0" xyz="0 -0.045 -0.006"/>
    <axis xyz="0 1 0"/>
    <command_interface name="velocity">
      <param name="min">-1</param>
      <param name="max">1</param>
    </command_interface>
    <state_interface name="position"/>
    <state_interface name="velocity"/>
    <state_interface name="acceleration"/>
  </joint>
  <link name="back_right_wheel">
    <visual>
      <geometry>
        <mesh filename="package://anveshika_description/meshes/rover/wheel.stl" scale="0.001 0.001 0.001"/>
      </geometry>
      <origin rpy="-1.5707963267948966 0 0" xyz="0 0 0"/>
    </visual>
    <collision>
      <geometry>
        <cylinder length="0.1" radius="0.06"/>
      </geometry>
      <origin rpy="-1.5707963267948966 0 0" xyz="0 0.05 0"/>
    </collision>
    <inertial>
      <origin rpy="-1.5707963267948966 0 0" xyz="0 0 0"/>
      <mass value="0.45"/>
      <inertia ixx="0.001735" ixy="0" ixz="0" iyy="0.001735" iyz="0" izz="0.0008776"/>
    </inertial>
  </link>
  <gazebo reference="back_right_wheel">
    <material>Gazebo/Red</material>
  </gazebo>
  <joint name="back_right_wheel_joint" type="continuous">
    <parent link="back_right_motor_mount"/>
    <child link="back_right_wheel"/>
    <origin rpy="0 0 0" xyz="0 -0.045 -0.006"/>
    <axis xyz="0 1 0"/>
    <command_interface name="velocity">
      <param name="min">-1</param>
      <param name="max">1</param>
    </command_interface>
    <state_interface name="position"/>
    <state_interface name="velocity"/>
    <state_interface name="acceleration"/>
  </joint>
  <gazebo>
    <plugin filename="gz-sim-joint-state-publisher-system" name="gz::sim::systems::JointStatePublisher">
      <update_rate>50</update_rate>
      <joint_name>base_left_bogie_joint</joint_name>
      <joint_name>base_right_bogie_joint</joint_name>
      <joint_name>left_bogie_front_left_motor_mount_joint</joint_name>
      <joint_name>left_bogie_back_left_motor_mount_joint</joint_name>
      <joint_name>right_bogie_front_right_motor_mount_joint</joint_name>
      <joint_name>right_bogie_back_right_motor_mount_joint</joint_name>
      <joint_name>front_left_wheel_joint</joint_name>
      <joint_name>back_left_wheel_joint</joint_name>
      <joint_name>front_right_wheel_joint</joint_name>
      <joint_name>back_right_wheel_joint</joint_name>
      <topic>/joint_states</topic>
    </plugin>
    <plugin filename="gz-sim-sensors-system" name="gz::sim::systems::Sensors">
      <render_engine>ogre2</render_engine>
    </plugin>
    <plugin filename="gz-sim-imu-system" name="gz::sim::systems::Imu"/>
  </gazebo>
  <joint name="laser_joint" type="fixed">
    <parent link="base_link"/>
    <child link="laser_frame"/>
    <origin rpy="3.14159265 0 0" xyz="0 0 -0.04"/>
  </joint>
  <link name="laser_frame">
    <visual>
      <geometry>
        <cylinder length="0.05" radius="0.05"/>
      </geometry>
      <origin rpy="0 0 0" xyz="0 0 0"/>
      <material name="Grey">
        <color rgba="0.6 0.6 0.6 1"/>
      </material>
    </visual>
    <collision>
      <geometry>
        <cylinder length="0.05" radius="0.05"/>
      </geometry>
      <origin rpy="0 0 0" xyz="0 0 0"/>
    </collision>
    <inertial>
      <mass value="0.3"/>
      <origin rpy="0 0 0" xyz="0 0 0"/>
      <inertia ixx="0.001" ixy="0.0" ixz="0.0" iyy="0.001" iyz="0.0" izz="0.001"/>
    </inertial>
  </link>
  <gazebo reference="laser_frame">
    <sensor name="laser" type="gpu_lidar">
      <always_on>1</always_on>
      <visualize>true</visualize>
      <pose>0 0 0 0 0 0</pose>
      <update_rate>50</update_rate>
      <topic>scan</topic>
      <gz_frame_id>laser_frame</gz_frame_id>
      <lidar>
        <scan>
          <horizontal>
            <samples>360</samples>
            <min_angle>-3.14159265</min_angle>
            <max_angle>3.14159265</max_angle>
          </horizontal>
        </scan>
        <range>
          <min>0.3</min>
          <max>12</max>
        </range>
        <noise>
          <type>gaussian</type>
          <mean>0.0</mean>
          <stddev>0.025</stddev>
        </noise>
      </lidar>
    </sensor>
  </gazebo>
</robot>
